1. Aatif Sayed (), Haseeb Hasan (hh508)
2. The server and client sockets are created but there are errors 
because the address is already in use so the connection is refused

[S]: Server socket created
[C]: Client socket created
Done.
Exception in thread server:
Traceback (most recent call last):
  File "/usr/lib/python2.7/threading.py", line 801, in __bootstrap_inner
    self.run()
  File "/usr/lib/python2.7/threading.py", line 754, in run
    self.__target(*self.__args, **self.__kwargs)
  File "proj.py", line 16, in server
    ss.bind(server_binding)
  File "/usr/lib/python2.7/socket.py", line 228, in meth
    return getattr(self._sock,name)(*args)
error: [Errno 98] Address already in use

Exception in thread client:
Traceback (most recent call last):
  File "/usr/lib/python2.7/threading.py", line 801, in __bootstrap_inner
    self.run()
  File "/usr/lib/python2.7/threading.py", line 754, in run
    self.__target(*self.__args, **self.__kwargs)
  File "proj.py", line 47, in client
    cs.connect(server_binding)
  File "/usr/lib/python2.7/socket.py", line 228, in meth
    return getattr(self._sock,name)(*args)
error: [Errno 111] Connection refused

3. 
4. 
5. 
6. 